<?xml version="1.0"?>
<mujoco>
    <compiler angle="radian" coordinate="local" meshdir="/home/lyw/project/task_official/DexterousHands_dexpoint/assets/mjcf/open_ai_assets/stls/hand/" texturedir="../textures"></compiler>
    <option timestep="0.002" iterations="20" apirate="200">
        <flag warmstart="enable"></flag>
    </option>

    
    <size njmax="500" nconmax="100" nuser_jnt="1" nuser_site="1" nuser_tendon="1" nuser_sensor="1" nuser_actuator="16" nstack="600000"></size>

    <visual>
        <map fogstart="3" fogend="5" force="0.1"></map>
        <quality shadowsize="4096"></quality>
    </visual>

    <default>
        <default class="robot1:asset_class">
            <geom friction="1 0.005 0.001" condim="3" margin="0.0005" contype="1" conaffinity="1"></geom>
            <joint limited="true" damping="0.1" armature="0.001" margin="0.01" frictionloss="0.001"></joint>
            <site size="0.005" rgba="0.4 0.9 0.4 1"></site>
            <general ctrllimited="true" forcelimited="true"></general>
        </default>
        <default class="robot1:D_Touch">
            <site type="box" size="0.009 0.004 0.013" pos="0 -0.004 0.018" rgba="0.8 0.8 0.8 0.15" group="4"></site>
        </default>
        <default class="robot1:DC_Hand">
            <geom material="robot1:MatColl" contype="1" conaffinity="0" group="4"></geom>
        </default>
        <default class="robot1:D_Vizual">
            <geom material="robot1:MatViz" contype="0" conaffinity="0" group="1" type="mesh"></geom>
        </default>
        <default class="robot1:free">
            <joint type="free" damping="0" armature="0" limited="false"></joint>
        </default>
    </default>

    <contact>
        <pair geom1="robot1:C_ffdistal" geom2="robot1:C_thdistal" condim="1"></pair>
        <pair geom1="robot1:C_ffmiddle" geom2="robot1:C_thdistal" condim="1"></pair>
        <pair geom1="robot1:C_ffproximal" geom2="robot1:C_thdistal" condim="1"></pair>
        <pair geom1="robot1:C_mfproximal" geom2="robot1:C_thdistal" condim="1"></pair>
        <pair geom1="robot1:C_mfdistal" geom2="robot1:C_thdistal" condim="1"></pair>
        <pair geom1="robot1:C_rfdistal" geom2="robot1:C_thdistal" condim="1"></pair>
        <pair geom1="robot1:C_lfdistal" geom2="robot1:C_thdistal" condim="1"></pair>
        <pair geom1="robot1:C_palm0" geom2="robot1:C_thdistal" condim="1"></pair>
        <pair geom1="robot1:C_mfdistal" geom2="robot1:C_ffdistal" condim="1"></pair>
        <pair geom1="robot1:C_rfdistal" geom2="robot1:C_mfdistal" condim="1"></pair>
        <pair geom1="robot1:C_lfdistal" geom2="robot1:C_rfdistal" condim="1"></pair>
        <pair geom1="robot1:C_mfproximal" geom2="robot1:C_ffproximal" condim="1"></pair>
        <pair geom1="robot1:C_rfproximal" geom2="robot1:C_mfproximal" condim="1"></pair>
        <pair geom1="robot1:C_lfproximal" geom2="robot1:C_rfproximal" condim="1"></pair>
        <pair geom1="robot1:C_lfdistal" geom2="robot1:C_rfdistal" condim="1"></pair>
        <pair geom1="robot1:C_lfdistal" geom2="robot1:C_mfdistal" condim="1"></pair>
        <pair geom1="robot1:C_lfdistal" geom2="robot1:C_rfmiddle" condim="1"></pair>
        <pair geom1="robot1:C_lfmiddle" geom2="robot1:C_rfdistal" condim="1"></pair>
        <pair geom1="robot1:C_lfmiddle" geom2="robot1:C_rfmiddle" condim="1"></pair>
    </contact>

    <tendon>
        <fixed name="robot1:T_FFJ1c" limited="true" range="-0.001 0.001">
            <joint joint="robot1:FFJ0" coef="0.00705"></joint>
            <joint joint="robot1:FFJ1" coef="-0.00805"></joint>
        </fixed>
        <fixed name="robot1:T_MFJ1c" limited="true" range="-0.001 0.001">
            <joint joint="robot1:MFJ0" coef="0.00705"></joint>
            <joint joint="robot1:MFJ1" coef="-0.00805"></joint>
        </fixed>
        <fixed name="robot1:T_RFJ1c" limited="true" range="-0.001 0.001">
            <joint joint="robot1:RFJ0" coef="0.00705"></joint>
            <joint joint="robot1:RFJ1" coef="-0.00805"></joint>
        </fixed>
        <fixed name="robot1:T_LFJ1c" limited="true" range="-0.001 0.001">
            <joint joint="robot1:LFJ0" coef="0.00705"></joint>
            <joint joint="robot1:LFJ1" coef="-0.00805"></joint>
        </fixed>

    </tendon>

    <sensor>
        <jointpos name="robot1:Sjp_WRJ1" joint="robot1:WRJ1"></jointpos>
        <jointpos name="robot1:Sjp_WRJ0" joint="robot1:WRJ0"></jointpos>
        <jointpos name="robot1:Sjp_FFJ3" joint="robot1:FFJ3"></jointpos>
        <jointpos name="robot1:Sjp_FFJ2" joint="robot1:FFJ2"></jointpos>
        <jointpos name="robot1:Sjp_FFJ1" joint="robot1:FFJ1"></jointpos>
        <jointpos name="robot1:Sjp_FFJ0" joint="robot1:FFJ0"></jointpos>
        <jointpos name="robot1:Sjp_MFJ3" joint="robot1:MFJ3"></jointpos>
        <jointpos name="robot1:Sjp_MFJ2" joint="robot1:MFJ2"></jointpos>
        <jointpos name="robot1:Sjp_MFJ1" joint="robot1:MFJ1"></jointpos>
        <jointpos name="robot1:Sjp_MFJ0" joint="robot1:MFJ0"></jointpos>
        <jointpos name="robot1:Sjp_RFJ3" joint="robot1:RFJ3"></jointpos>
        <jointpos name="robot1:Sjp_RFJ2" joint="robot1:RFJ2"></jointpos>
        <jointpos name="robot1:Sjp_RFJ1" joint="robot1:RFJ1"></jointpos>
        <jointpos name="robot1:Sjp_RFJ0" joint="robot1:RFJ0"></jointpos>
        <jointpos name="robot1:Sjp_LFJ4" joint="robot1:LFJ4"></jointpos>
        <jointpos name="robot1:Sjp_LFJ3" joint="robot1:LFJ3"></jointpos>
        <jointpos name="robot1:Sjp_LFJ2" joint="robot1:LFJ2"></jointpos>
        <jointpos name="robot1:Sjp_LFJ1" joint="robot1:LFJ1"></jointpos>
        <jointpos name="robot1:Sjp_LFJ0" joint="robot1:LFJ0"></jointpos>
        <jointpos name="robot1:Sjp_THJ4" joint="robot1:THJ4"></jointpos>
        <jointpos name="robot1:Sjp_THJ3" joint="robot1:THJ3"></jointpos>
        <jointpos name="robot1:Sjp_THJ2" joint="robot1:THJ2"></jointpos>
        <jointpos name="robot1:Sjp_THJ1" joint="robot1:THJ1"></jointpos>
        <jointpos name="robot1:Sjp_THJ0" joint="robot1:THJ0"></jointpos>
        <touch name="robot1:ST_Tch_fftip" site="robot1:Tch_fftip"></touch>
        <touch name="robot1:ST_Tch_mftip" site="robot1:Tch_mftip"></touch>
        <touch name="robot1:ST_Tch_rftip" site="robot1:Tch_rftip"></touch>
        <touch name="robot1:ST_Tch_lftip" site="robot1:Tch_lftip"></touch>
        <touch name="robot1:ST_Tch_thtip" site="robot1:Tch_thtip"></touch>
    </sensor>

    <actuator>
        <position name="robot1:A_WRJ1" class="robot1:asset_class" user="2038" joint="robot1:WRJ1" ctrlrange="-0.489 0.14" kp="5" forcerange="-4.785 4.785"></position>
        <position name="robot1:A_WRJ0" class="robot1:asset_class" user="2036" joint="robot1:WRJ0" ctrlrange="-0.698 0.489" kp="5" forcerange="-2.175 2.175"></position>
        <position name="robot1:A_FFJ3" class="robot1:asset_class" user="2004" joint="robot1:FFJ3" ctrlrange="-0.349 0.349" kp="1" forcerange="-0.9 0.9"></position>
        <position name="robot1:A_FFJ2" class="robot1:asset_class" user="2002" joint="robot1:FFJ2" ctrlrange="0 1.571" kp="1" forcerange="-0.9 0.9"></position>
        <position name="robot1:A_FFJ1" class="robot1:asset_class" user="2000" joint="robot1:FFJ1" ctrlrange="0 1.571" kp="1" forcerange="-0.7245 0.7245"></position>
        <position name="robot1:A_MFJ3" class="robot1:asset_class" user="2010" joint="robot1:MFJ3" ctrlrange="-0.349 0.349" kp="1" forcerange="-0.9 0.9"></position>
        <position name="robot1:A_MFJ2" class="robot1:asset_class" user="2008" joint="robot1:MFJ2" ctrlrange="0 1.571" kp="1" forcerange="-0.9 0.9"></position>
        <position name="robot1:A_MFJ1" class="robot1:asset_class" user="2006" joint="robot1:MFJ1" ctrlrange="0 1.571" kp="1" forcerange="-0.7245 0.7245"></position>
        <position name="robot1:A_RFJ3" class="robot1:asset_class" user="2016" joint="robot1:RFJ3" ctrlrange="-0.349 0.349" kp="1" forcerange="-0.9 0.9"></position>
        <position name="robot1:A_RFJ2" class="robot1:asset_class" user="2014" joint="robot1:RFJ2" ctrlrange="0 1.571" kp="1" forcerange="-0.9 0.9"></position>
        <position name="robot1:A_RFJ1" class="robot1:asset_class" user="2012" joint="robot1:RFJ1" ctrlrange="0 1.571" kp="1" forcerange="-0.7245 0.7245"></position>
        <position name="robot1:A_LFJ4" class="robot1:asset_class" user="2024" joint="robot1:LFJ4" ctrlrange="0 0.785" kp="1" forcerange="-0.9 0.9"></position>
        <position name="robot1:A_LFJ3" class="robot1:asset_class" user="2022" joint="robot1:LFJ3" ctrlrange="-0.349 0.349" kp="1" forcerange="-0.9 0.9"></position>
        <position name="robot1:A_LFJ2" class="robot1:asset_class" user="2020" joint="robot1:LFJ2" ctrlrange="0 1.571" kp="1" forcerange="-0.9 0.9"></position>
        <position name="robot1:A_LFJ1" class="robot1:asset_class" user="2018" joint="robot1:LFJ1" ctrlrange="0 1.571" kp="1" forcerange="-0.7245 0.7245"></position>
        <position name="robot1:A_THJ4" class="robot1:asset_class" user="2034" joint="robot1:THJ4" ctrlrange="-1.047 1.047" kp="1" forcerange="-2.3722 2.3722"></position>
        <position name="robot1:A_THJ3" class="robot1:asset_class" user="2032" joint="robot1:THJ3" ctrlrange="0 1.222" kp="1" forcerange="-1.45 1.45"></position>
        <position name="robot1:A_THJ2" class="robot1:asset_class" user="2030" joint="robot1:THJ2" ctrlrange="-0.209 0.209" kp="1" forcerange="-0.99 0.99"></position>
        <position name="robot1:A_THJ1" class="robot1:asset_class" user="2028" joint="robot1:THJ1" ctrlrange="-0.524 0.524" kp="1" forcerange="-0.99 0.99"></position>
        <position name="robot1:A_THJ0" class="robot1:asset_class" user="2026" joint="robot1:THJ0" ctrlrange="-1.571 0" kp="1" forcerange="-0.81 0.81"></position>
    </actuator>


    <asset>
        <texture type="skybox" builtin="gradient" rgb1="0.44 0.85 0.56" rgb2="0.46 0.87 0.58" width="32" height="32"></texture>

        <texture name="robot1:texplane" type="2d" builtin="checker" rgb1="0.2 0.3 0.4" rgb2="0.1 0.15 0.2" width="512" height="512"></texture>
        <texture name="robot1:texgeom" type="cube" builtin="flat" mark="cross" width="127" height="127" rgb1="0.3 0.6 0.5" rgb2="0.3 0.6 0.5" markrgb="0 0 0" random="0.01"></texture>

        <material name="robot1:MatGnd" reflectance="0.5" texture="robot1:texplane" texrepeat="1 1" texuniform="true"></material>
        <material name="robot1:MatColl" specular="1" shininess="0.3" reflectance="0.5" rgba="0.4 0.5 0.6 1"></material>
        <material name="robot1:MatViz" specular="0.75" shininess="0.1" reflectance="0.5" rgba="0.93 0.93 0.93 1"></material>
        <material name="robot1:object" texture="robot1:texgeom" texuniform="false"></material>
        <material name="floor_mat" specular="0" shininess="0.5" reflectance="0" rgba="0.2 0.2 0.2 0"></material>

        <mesh name="robot1:forearm" file="forearm_electric.stl"></mesh>
        <mesh name="robot1:forearm_cvx" file="forearm_electric_cvx.stl"></mesh>
        <mesh name="robot1:wrist" scale="0.001 0.001 0.001" file="wrist.stl"></mesh>
        <mesh name="robot1:palm" scale="0.001 0.001 0.001" file="palm.stl"></mesh>
        <mesh name="robot1:knuckle" scale="0.001 0.001 0.001" file="knuckle.stl"></mesh>
        <mesh name="robot1:F3" scale="0.001 0.001 0.001" file="F3.stl"></mesh>
        <mesh name="robot1:F2" scale="0.001 0.001 0.001" file="F2.stl"></mesh>
        <mesh name="robot1:F1" scale="0.001 0.001 0.001" file="F1.stl"></mesh>
        <mesh name="robot1:lfmetacarpal" scale="0.001 0.001 0.001" file="lfmetacarpal.stl"></mesh>
        <mesh name="robot1:TH3_z" scale="0.001 0.001 0.001" file="TH3_z.stl"></mesh>
        <mesh name="robot1:TH2_z" scale="0.001 0.001 0.001" file="TH2_z.stl"></mesh>
        <mesh name="robot1:TH1_z" scale="0.001 0.001 0.001" file="TH1_z.stl"></mesh>

    </asset>

    <worldbody>
        <body name="robot1:hand mount" pos="1 1.25 0.15" euler="1.5708 0 3.14159">
            <inertial mass="0.1" pos="0 0 0" diaginertia="0.001 0.001 0.001"></inertial>
            <body childclass="robot1:asset_class" name="robot1:forearm" pos="0 0.01 0" euler="0 0 0">
                <inertial pos="0.001 -0.002 0.29" quat="0.982 -0.016 0 -0.188" mass="4" diaginertia="0.01 0.01 0.0075"></inertial>
                <geom class="robot1:D_Vizual" pos="0 0.01 0.04" name="robot1:V_forearm" mesh="robot1:forearm" euler="0 0 1.57"></geom>
                <geom class="robot1:DC_Hand" name="robot1:C_forearm" type="mesh" mesh="robot1:forearm_cvx" pos="0 0.01 0.04" euler="0 0 1.57" rgba="0.4 0.5 0.6 0.7"></geom>
                <body name="robot1:wrist" pos="0 0 0.256">
                    <inertial pos="0.003 0 0.016" quat="0.504 0.496 0.495 0.504" mass="0.3" diaginertia="0.001 0.001 0.001"></inertial>
                    <joint name="robot1:WRJ1" type="hinge" pos="0 0 0" axis="0 1 0" range="-0.489 0.14" damping="0.5" armature="0.005" user="1123"></joint>
                    <geom class="robot1:D_Vizual" name="robot1:V_wrist" mesh="robot1:wrist"></geom>
                    <geom class="robot1:DC_Hand" name="robot1:C_wrist" type="capsule" pos="0 0 0" quat="0.707 0.707 0 0" size="0.015 0.01" rgba="0.4 0.5 0.6 0.1"></geom>
                    <body name="robot1:palm" pos="0 0 0.034">
                        <inertial pos="0.006 0 0.036" quat="0.716 0.044 0.075 0.693" mass="0.3" diaginertia="0.001 0.001 0.001"></inertial>
                        <joint name="robot1:WRJ0" type="hinge" pos="0 0 0" axis="1 0 0" range="-0.698 0.489" damping="0.5" armature="0.005" user="1122"></joint>
                        <geom class="robot1:D_Vizual" name="robot1:V_palm" mesh="robot1:palm"></geom>
                        <geom class="robot1:DC_Hand" name="robot1:C_palm0" type="box" pos="0.011 0 0.038" size="0.032 0.0111 0.049" rgba="0.4 0.5 0.6 0.1"></geom>
                        <geom class="robot1:DC_Hand" name="robot1:C_palm1" type="box" pos="-0.032 0 0.014" size="0.011 0.0111 0.025" rgba="0.4 0.5 0.6 0.1"></geom>
                        <body name="robot1:ffknuckle" pos="0.033 0 0.095">
                            <inertial pos="0 0 0" quat="0.52 0.854 0.006 -0.003" mass="0.008" diaginertia="1e-05 1e-05 1e-05"></inertial>
                            <joint name="robot1:FFJ3" type="hinge" pos="0 0 0" axis="0 1 0" range="-0.349 0.349" user="1103"></joint>
                            <geom class="robot1:D_Vizual" name="robot1:V_ffknuckle" mesh="robot1:knuckle"></geom>
                            <body name="robot1:ffproximal" pos="0 0 0">
                                <inertial pos="0 0 0.023" quat="0.707 -0.004 0.004 0.707" mass="0.014" diaginertia="1e-05 1e-05 1e-05"></inertial>
                                <joint name="robot1:FFJ2" type="hinge" pos="0 0 0" axis="1 0 0" range="0 1.571" user="1102"></joint>
                                <geom class="robot1:D_Vizual" name="robot1:V_ffproximal" mesh="robot1:F3"></geom>
                                <geom class="robot1:DC_Hand" name="robot1:C_ffproximal" type="capsule" pos="0 0 0.0225" size="0.01 0.0225"></geom>
                                <body name="robot1:ffmiddle" pos="0 0 0.045">
                                    <inertial pos="0 0 0.011" quat="0.707 0 0 0.707" mass="0.012" diaginertia="1e-05 1e-05 1e-05"></inertial>
                                    <joint name="robot1:FFJ1" type="hinge" pos="0 0 0" axis="1 0 0" range="0 1.571" user="1101"></joint>
                                    <geom class="robot1:D_Vizual" name="robot1:V_ffmiddle" mesh="robot1:F2"></geom>
                                    <geom class="robot1:DC_Hand" name="robot1:C_ffmiddle" type="capsule" pos="0 0 0.0125" size="0.00805 0.0125"></geom>
                                    <body name="robot1:ffdistal" pos="0 0 0.025">
                                        <inertial pos="0 0 0.015" quat="0.707 -0.003 0.003 0.707" mass="0.01" diaginertia="1e-05 1e-05 1e-05"></inertial>
                                        <joint name="robot1:FFJ0" type="hinge" pos="0 0 0" axis="1 0 0" range="0 1.571" user="1100"></joint>
                                        <geom class="robot1:D_Vizual" name="robot1:V_ffdistal" pos="0 0 0.001" mesh="robot1:F1"></geom>
                                        <geom class="robot1:DC_Hand" name="robot1:C_ffdistal" type="capsule" pos="0 0 0.012" size="0.00705 0.012" condim="4"></geom>
                                        <site name="robot1:S_fftip" pos="0 0 0.026" group="3"></site>
                                        <site class="robot1:D_Touch" name="robot1:Tch_fftip"></site>
                                    </body>
                                </body>
                            </body>
                        </body>
                        <body name="robot1:mfknuckle" pos="0.011 0 0.099">
                            <inertial pos="0 0 0" quat="0.52 0.854 0.006 -0.003" mass="0.008" diaginertia="1e-05 1e-05 1e-05"></inertial>
                            <joint name="robot1:MFJ3" type="hinge" pos="0 0 0" axis="0 1 0" range="-0.349 0.349" user="1107"></joint>
                            <geom class="robot1:D_Vizual" name="robot1:V_mfknuckle" mesh="robot1:knuckle"></geom>
                            <body name="robot1:mfproximal" pos="0 0 0">
                                <inertial pos="0 0 0.023" quat="0.707 -0.004 0.004 0.707" mass="0.014" diaginertia="1e-05 1e-05 1e-05"></inertial>
                                <joint name="robot1:MFJ2" type="hinge" pos="0 0 0" axis="1 0 0" range="0 1.571" user="1106"></joint>
                                <geom class="robot1:D_Vizual" name="robot1:V_mfproximal" mesh="robot1:F3"></geom>
                                <geom class="robot1:DC_Hand" name="robot1:C_mfproximal" type="capsule" pos="0 0 0.0225" size="0.01 0.0225"></geom>
                                <body name="robot1:mfmiddle" pos="0 0 0.045">
                                    <inertial pos="0 0 0.012" quat="0.707 0 0 0.707" mass="0.012" diaginertia="1e-05 1e-05 1e-05"></inertial>
                                    <joint name="robot1:MFJ1" type="hinge" pos="0 0 0" axis="1 0 0" range="0 1.571" user="1105"></joint>
                                    <geom class="robot1:D_Vizual" name="robot1:V_mfmiddle" mesh="robot1:F2"></geom>
                                    <geom class="robot1:DC_Hand" name="robot1:C_mfmiddle" type="capsule" pos="0 0 0.0125" size="0.00805 0.0125"></geom>
                                    <body name="robot1:mfdistal" pos="0 0 0.025">
                                        <inertial pos="0 0 0.015" quat="0.707 -0.003 0.003 0.707" mass="0.01" diaginertia="1e-05 1e-05 1e-05"></inertial>
                                        <joint name="robot1:MFJ0" type="hinge" pos="0 0 0" axis="1 0 0" range="0 1.571" user="1104"></joint>
                                        <geom class="robot1:D_Vizual" name="robot1:V_mfdistal" mesh="robot1:F1"></geom>
                                        <geom class="robot1:DC_Hand" name="robot1:C_mfdistal" type="capsule" pos="0 0 0.012" size="0.00705 0.012" condim="4"></geom>
                                        <site name="robot1:S_mftip" pos="0 0 0.026" group="3"></site>
                                        <site class="robot1:D_Touch" name="robot1:Tch_mftip"></site>
                                    </body>
                                </body>
                            </body>
                        </body>
                        <body name="robot1:rfknuckle" pos="-0.011 0 0.095">
                            <inertial pos="0 0 0" quat="0.52 0.854 0.006 -0.003" mass="0.008" diaginertia="1e-05 1e-05 1e-05"></inertial>
                            <joint name="robot1:RFJ3" type="hinge" pos="0 0 0" axis="0 1 0" range="-0.349 0.349" user="1111"></joint>
                            <geom class="robot1:D_Vizual" name="robot1:V_rfknuckle" mesh="robot1:knuckle"></geom>
                            <body name="robot1:rfproximal" pos="0 0 0">
                                <inertial pos="0 0 0.023" quat="0.707 -0.004 0.004 0.707" mass="0.014" diaginertia="1e-05 1e-05 1e-05"></inertial>
                                <joint name="robot1:RFJ2" type="hinge" pos="0 0 0" axis="1 0 0" range="0 1.571" user="1110"></joint>
                                <geom class="robot1:D_Vizual" name="robot1:V_rfproximal" mesh="robot1:F3"></geom>
                                <geom class="robot1:DC_Hand" name="robot1:C_rfproximal" type="capsule" pos="0 0 0.0225" size="0.01 0.0225"></geom>
                                <body name="robot1:rfmiddle" pos="0 0 0.045">
                                    <inertial pos="0 0 0.012" quat="0.707 0 0 0.707" mass="0.012" diaginertia="1e-05 1e-05 1e-05"></inertial>
                                    <joint name="robot1:RFJ1" type="hinge" pos="0 0 0" axis="1 0 0" range="0 1.571" user="1109"></joint>
                                    <geom class="robot1:D_Vizual" name="robot1:V_rfmiddle" mesh="robot1:F2"></geom>
                                    <geom class="robot1:DC_Hand" name="robot1:C_rfmiddle" type="capsule" pos="0 0 0.0125" size="0.00805 0.0125"></geom>
                                    <body name="robot1:rfdistal" pos="0 0 0.025">
                                        <inertial pos="0 0 0.015" quat="0.707 -0.003 0.003 0.707" mass="0.01" diaginertia="1e-05 1e-05 1e-05"></inertial>
                                        <joint name="robot1:RFJ0" type="hinge" pos="0 0 0" axis="1 0 0" range="0 1.571" user="1108"></joint>
                                        <geom class="robot1:D_Vizual" name="robot1:V_rfdistal" mesh="robot1:F1" pos="0 0 0.001"></geom>
                                        <geom class="robot1:DC_Hand" name="robot1:C_rfdistal" type="capsule" pos="0 0 0.012" size="0.00705 0.012" condim="4"></geom>
                                        <site name="robot1:S_rftip" pos="0 0 0.026" group="3"></site>
                                        <site class="robot1:D_Touch" name="robot1:Tch_rftip"></site>
                                    </body>
                                </body>
                            </body>
                        </body>
                        <body name="robot1:lfmetacarpal" pos="-0.017 0 0.044">
                            <inertial pos="-0.014 0.001 0.014" quat="0.709 -0.092 -0.063 0.696" mass="0.075" diaginertia="1e-05 1e-05 1e-05"></inertial>
                            <joint name="robot1:LFJ4" type="hinge" pos="0 0 0" axis="0.571 0 0.821" range="0 0.785" user="1116"></joint>
                            <geom class="robot1:D_Vizual" name="robot1:V_lfmetacarpal" pos="-0.016 0 -0.023" mesh="robot1:lfmetacarpal"></geom>
                            <geom class="robot1:DC_Hand" name="robot1:C_lfmetacarpal" type="box" pos="-0.0165 0 0.01" size="0.0095 0.0111 0.025" rgba="0.4 0.5 0.6 0.2"></geom>
                            <body name="robot1:lfknuckle" pos="-0.017 0 0.044">
                                <inertial pos="0 0 0" quat="0.52 0.854 0.006 -0.003" mass="0.008" diaginertia="1e-05 1e-05 1e-05"></inertial>
                                <joint name="robot1:LFJ3" type="hinge" pos="0 0 0" axis="0 1 0" range="-0.349 0.349" user="1115"></joint>
                                <geom class="robot1:D_Vizual" name="robot1:V_lfknuckle" mesh="robot1:knuckle"></geom>
                                <body name="robot1:lfproximal" pos="0 0 0">
                                    <inertial pos="0 0 0.023" quat="0.707 -0.004 0.004 0.707" mass="0.014" diaginertia="1e-05 1e-05 1e-05"></inertial>
                                    <joint name="robot1:LFJ2" type="hinge" pos="0 0 0" axis="1 0 0" range="0 1.571" user="1114"></joint>
                                    <geom class="robot1:D_Vizual" name="robot1:V_lfproximal" mesh="robot1:F3"></geom>
                                    <geom class="robot1:DC_Hand" name="robot1:C_lfproximal" type="capsule" pos="0 0 0.0225" size="0.01 0.0225"></geom>
                                    <body name="robot1:lfmiddle" pos="0 0 0.045">
                                        <inertial pos="0 0 0.012" quat="0.707 0 0 0.707" mass="0.012" diaginertia="1e-05 1e-05 1e-05"></inertial>
                                        <joint name="robot1:LFJ1" type="hinge" pos="0 0 0" axis="1 0 0" range="0 1.571" user="1113"></joint>
                                        <geom class="robot1:D_Vizual" name="robot1:V_lfmiddle" mesh="robot1:F2"></geom>
                                        <geom class="robot1:DC_Hand" name="robot1:C_lfmiddle" type="capsule" pos="0 0 0.0125" size="0.00805 0.0125"></geom>
                                        <body name="robot1:lfdistal" pos="0 0 0.025">
                                            <inertial pos="0 0 0.015" quat="0.707 -0.003 0.003 0.707" mass="0.01" diaginertia="1e-05 1e-05 1e-05"></inertial>
                                            <joint name="robot1:LFJ0" type="hinge" pos="0 0 0" axis="1 0 0" range="0 1.571" user="1112"></joint>
                                            <geom class="robot1:D_Vizual" name="robot1:V_lfdistal" mesh="robot1:F1" pos="0 0 0.001"></geom>
                                            <geom class="robot1:DC_Hand" name="robot1:C_lfdistal" type="capsule" pos="0 0 0.012" size="0.00705 0.012" condim="4"></geom>
                                            <site name="robot1:S_lftip" pos="0 0 0.026" group="3"></site>
                                            <site class="robot1:D_Touch" name="robot1:Tch_lftip"></site>
                                        </body>
                                    </body>
                                </body>
                            </body>
                        </body>
                        <body name="robot1:thbase" pos="0.034 -0.009 0.029" axisangle="0 1 0 0.785">
                            <inertial pos="0 0 0" mass="0.01" diaginertia="1e-05 1e-05 1e-05"></inertial>
                            <joint name="robot1:THJ4" type="hinge" pos="0 0 0" axis="0 0 -1" range="-1.047 1.047" user="1121"></joint>
                            <geom name="robot1:V_thbase" type="box" group="1" pos="0 0 0" size="0.001 0.001 0.001"></geom>
                            <body name="robot1:thproximal" pos="0 0 0">
                                <inertial pos="0 0 0.017" quat="0.982 0 0.001 0.191" mass="0.016" diaginertia="1e-05 1e-05 1e-05"></inertial>
                                <joint name="robot1:THJ3" type="hinge" pos="0 0 0" axis="1 0 0" range="0 1.222" user="1120"></joint>
                                <geom class="robot1:D_Vizual" name="robot1:V_thproximal" mesh="robot1:TH3_z"></geom>
                                <geom class="robot1:DC_Hand" name="robot1:C_thproximal" type="capsule" pos="0 0 0.019" size="0.013 0.019" rgba="0.4 0.5 0.6 0.1"></geom>
                                <body name="robot1:thhub" pos="0 0 0.038">
                                    <inertial pos="0 0 0" mass="0.002" diaginertia="1e-05 1e-05 1e-05"></inertial>
                                    <joint name="robot1:THJ2" type="hinge" pos="0 0 0" axis="1 0 0" range="-0.209 0.209" user="1119"></joint>
                                    <geom name="robot1:V_thhub" type="box" group="1" pos="0 0 0" size="0.001 0.001 0.001"></geom>
                                    <body name="robot1:thmiddle" pos="0 0 0">
                                        <inertial pos="0 0 0.016" quat="1 -0.001 -0.007 0.003" mass="0.016" diaginertia="1e-05 1e-05 1e-05"></inertial>
                                        <joint name="robot1:THJ1" type="hinge" pos="0 0 0" axis="0 1 0" range="-0.524 0.524" user="1118"></joint>
                                        <geom class="robot1:D_Vizual" name="robot1:V_thmiddle" mesh="robot1:TH2_z"></geom>
                                        <geom class="robot1:DC_Hand" name="robot1:C_thmiddle" type="capsule" pos="0 0 0.016" size="0.011 0.016"></geom>
                                        <body name="robot1:thdistal" pos="0 0 0.032">
                                            <inertial pos="0 0 0.016" quat="0.999 -0.005 -0.047 0.005" mass="0.016" diaginertia="1e-05 1e-05 1e-05"></inertial>
                                            <joint name="robot1:THJ0" type="hinge" pos="0 0 0" axis="0 1 0" range="-1.571 0" user="1117"></joint>
                                            <geom class="robot1:D_Vizual" name="robot1:V_thdistal" mesh="robot1:TH1_z"></geom>
                                            <geom class="robot1:DC_Hand" name="robot1:C_thdistal" type="capsule" pos="0 0 0.013" size="0.00918 0.013" condim="4"></geom>
                                            <site name="robot1:S_thtip" pos="0 0 0.0275" group="3"></site>
                                            <site class="robot1:D_Touch" name="robot1:Tch_thtip" size="0.005 0.011 0.016" pos="-0.005 0 0.02"></site>
                                        </body>
                                    </body>
                                </body>
                            </body>
                        </body>
                    </body>
                </body>
            </body>
        </body>

        
        <light directional="true" ambient="0.2 0.2 0.2" diffuse="0.8 0.8 0.8" specular="0.3 0.3 0.3" castshadow="false" pos="0 1 4" dir="0 0 -1" name="light0"></light>
    </worldbody>
</mujoco>
